[ERROR] 2021-09-11 14:18:03,076 | /home/server-admin/Projects/Gopi/Training/apps/frappe/frappe/utils/error.py:
New Exception collected with id: 2021-09-11 14:18:02.605230-127.0.0.1-5e4
[ERROR] 2021-09-11 14:20:58,592 | /home/server-admin/Projects/Gopi/Training/apps/frappe/frappe/app.py:
Site: management
Form Dict: {
 "cmd": "frappe.desk.reportview.get",
 "doctype": "Payments",
 "fields": "[\"`tabPayments`.`name`\",\"`tabPayments`.`owner`\",\"`tabPayments`.`creation`\",\"`tabPayments`.`modified`\",\"`tabPayments`.`modified_by`\",\"`tabPayments`.`_user_tags`\",\"`tabPayments`.`_comments`\",\"`tabPayments`.`_assign`\",\"`tabPayments`.`_liked_by`\",\"`tabPayments`.`docstatus`\",\"`tabPayments`.`parent`\",\"`tabPayments`.`parenttype`\",\"`tabPayments`.`parentfield`\",\"`tabPayments`.`idx`\",\"`tabPayments`.`payment_type`\"]",
 "filters": "[]",
 "order_by": "`tabPayments`.`modified` desc",
 "page_length": "20",
 "start": "0",
 "view": "List",
 "with_comment_count": "true"
}
Request Error
Traceback (most recent call last):
  File "/home/server-admin/Projects/Gopi/Training/apps/frappe/frappe/app.py", line 67, in application
    response = frappe.api.handle()
  File "/home/server-admin/Projects/Gopi/Training/apps/frappe/frappe/api.py", line 59, in handle
    return frappe.handler.handle()
  File "/home/server-admin/Projects/Gopi/Training/apps/frappe/frappe/handler.py", line 24, in handle
    data = execute_cmd(cmd)
  File "/home/server-admin/Projects/Gopi/Training/apps/frappe/frappe/handler.py", line 64, in execute_cmd
    return frappe.call(method, **frappe.form_dict)
  File "/home/server-admin/Projects/Gopi/Training/apps/frappe/frappe/__init__.py", line 1075, in call
    return fn(*args, **newargs)
  File "/home/server-admin/Projects/Gopi/Training/apps/frappe/frappe/__init__.py", line 539, in wrapper_fn
    retval = fn(*args, **get_newargs(fn, kwargs))
  File "/home/server-admin/Projects/Gopi/Training/apps/frappe/frappe/desk/reportview.py", line 22, in get
    data = compress(execute(**args), args = args)
  File "/home/server-admin/Projects/Gopi/Training/apps/frappe/frappe/desk/reportview.py", line 27, in execute
    return DatabaseQuery(doctype).execute(*args, **kwargs)
  File "/home/server-admin/Projects/Gopi/Training/apps/frappe/frappe/model/db_query.py", line 96, in execute
    result = self.build_and_run()
  File "/home/server-admin/Projects/Gopi/Training/apps/frappe/frappe/model/db_query.py", line 130, in build_and_run
    return frappe.db.sql(query, as_dict=not self.as_list, debug=self.debug, update=self.update)
  File "/home/server-admin/Projects/Gopi/Training/apps/frappe/frappe/database/database.py", line 171, in sql
    self._cursor.execute(query)
  File "/home/server-admin/Projects/Gopi/Training/env/local/lib/python2.7/site-packages/pymysql/cursors.py", line 170, in execute
    result = self._query(query)
  File "/home/server-admin/Projects/Gopi/Training/env/local/lib/python2.7/site-packages/pymysql/cursors.py", line 328, in _query
    conn.query(q)
  File "/home/server-admin/Projects/Gopi/Training/env/local/lib/python2.7/site-packages/pymysql/connections.py", line 517, in query
    self._affected_rows = self._read_query_result(unbuffered=unbuffered)
  File "/home/server-admin/Projects/Gopi/Training/env/local/lib/python2.7/site-packages/pymysql/connections.py", line 732, in _read_query_result
    result.read()
  File "/home/server-admin/Projects/Gopi/Training/env/local/lib/python2.7/site-packages/pymysql/connections.py", line 1075, in read
    first_packet = self.connection._read_packet()
  File "/home/server-admin/Projects/Gopi/Training/env/local/lib/python2.7/site-packages/pymysql/connections.py", line 684, in _read_packet
    packet.check_error()
  File "/home/server-admin/Projects/Gopi/Training/env/local/lib/python2.7/site-packages/pymysql/protocol.py", line 220, in check_error
    err.raise_mysql_exception(self._data)
  File "/home/server-admin/Projects/Gopi/Training/env/local/lib/python2.7/site-packages/pymysql/err.py", line 109, in raise_mysql_exception
    raise errorclass(errno, errval)
InternalError: (1054, u"Unknown column 'tabPayments.assigned_by' in 'where clause'")
[ERROR] 2021-09-11 14:20:58,765 | /home/server-admin/Projects/Gopi/Training/apps/frappe/frappe/utils/error.py:
New Exception collected with id: 2021-09-11 14:20:58.593270-127.0.0.1-e9b
[ERROR] 2021-09-11 14:22:57,769 | /home/server-admin/Projects/Gopi/Training/apps/frappe/frappe/app.py:
Site: management
Form Dict: {
 "cmd": "frappe.desk.reportview.get",
 "doctype": "Payments",
 "fields": "[\"`tabPayments`.`name`\",\"`tabPayments`.`owner`\",\"`tabPayments`.`creation`\",\"`tabPayments`.`modified`\",\"`tabPayments`.`modified_by`\",\"`tabPayments`.`_user_tags`\",\"`tabPayments`.`_comments`\",\"`tabPayments`.`_assign`\",\"`tabPayments`.`_liked_by`\",\"`tabPayments`.`docstatus`\",\"`tabPayments`.`parent`\",\"`tabPayments`.`parenttype`\",\"`tabPayments`.`parentfield`\",\"`tabPayments`.`idx`\",\"`tabPayments`.`payment_type`\"]",
 "filters": "[]",
 "order_by": "`tabPayments`.`modified` desc",
 "page_length": "20",
 "start": "0",
 "view": "List",
 "with_comment_count": "true"
}
Request Error
Traceback (most recent call last):
  File "/home/server-admin/Projects/Gopi/Training/apps/frappe/frappe/app.py", line 67, in application
    response = frappe.api.handle()
  File "/home/server-admin/Projects/Gopi/Training/apps/frappe/frappe/api.py", line 59, in handle
    return frappe.handler.handle()
  File "/home/server-admin/Projects/Gopi/Training/apps/frappe/frappe/handler.py", line 24, in handle
    data = execute_cmd(cmd)
  File "/home/server-admin/Projects/Gopi/Training/apps/frappe/frappe/handler.py", line 64, in execute_cmd
    return frappe.call(method, **frappe.form_dict)
  File "/home/server-admin/Projects/Gopi/Training/apps/frappe/frappe/__init__.py", line 1075, in call
    return fn(*args, **newargs)
  File "/home/server-admin/Projects/Gopi/Training/apps/frappe/frappe/__init__.py", line 539, in wrapper_fn
    retval = fn(*args, **get_newargs(fn, kwargs))
  File "/home/server-admin/Projects/Gopi/Training/apps/frappe/frappe/desk/reportview.py", line 22, in get
    data = compress(execute(**args), args = args)
  File "/home/server-admin/Projects/Gopi/Training/apps/frappe/frappe/desk/reportview.py", line 27, in execute
    return DatabaseQuery(doctype).execute(*args, **kwargs)
  File "/home/server-admin/Projects/Gopi/Training/apps/frappe/frappe/model/db_query.py", line 96, in execute
    result = self.build_and_run()
  File "/home/server-admin/Projects/Gopi/Training/apps/frappe/frappe/model/db_query.py", line 130, in build_and_run
    return frappe.db.sql(query, as_dict=not self.as_list, debug=self.debug, update=self.update)
  File "/home/server-admin/Projects/Gopi/Training/apps/frappe/frappe/database/database.py", line 171, in sql
    self._cursor.execute(query)
  File "/home/server-admin/Projects/Gopi/Training/env/local/lib/python2.7/site-packages/pymysql/cursors.py", line 170, in execute
    result = self._query(query)
  File "/home/server-admin/Projects/Gopi/Training/env/local/lib/python2.7/site-packages/pymysql/cursors.py", line 328, in _query
    conn.query(q)
  File "/home/server-admin/Projects/Gopi/Training/env/local/lib/python2.7/site-packages/pymysql/connections.py", line 517, in query
    self._affected_rows = self._read_query_result(unbuffered=unbuffered)
  File "/home/server-admin/Projects/Gopi/Training/env/local/lib/python2.7/site-packages/pymysql/connections.py", line 732, in _read_query_result
    result.read()
  File "/home/server-admin/Projects/Gopi/Training/env/local/lib/python2.7/site-packages/pymysql/connections.py", line 1075, in read
    first_packet = self.connection._read_packet()
  File "/home/server-admin/Projects/Gopi/Training/env/local/lib/python2.7/site-packages/pymysql/connections.py", line 684, in _read_packet
    packet.check_error()
  File "/home/server-admin/Projects/Gopi/Training/env/local/lib/python2.7/site-packages/pymysql/protocol.py", line 220, in check_error
    err.raise_mysql_exception(self._data)
  File "/home/server-admin/Projects/Gopi/Training/env/local/lib/python2.7/site-packages/pymysql/err.py", line 109, in raise_mysql_exception
    raise errorclass(errno, errval)
InternalError: (1054, u"Unknown column 'tabPayments.assigned_by' in 'where clause'")
[ERROR] 2021-09-11 14:22:57,951 | /home/server-admin/Projects/Gopi/Training/apps/frappe/frappe/utils/error.py:
New Exception collected with id: 2021-09-11 14:22:57.770080-127.0.0.1-f8d
